Workbook

Sheet Inspeção das Instalações
A1: Ação | B1: Data_Registro | C1: Setor | D1: Categoria por Tópico do FMS | E1: Setor Responsável | F1: Apontamento | G1: Conteção Imediata ? | H1: Gravidade | I1: Urgência | J1: Tendência | K1: Pontuação GUT | L1: Prioridade GUT | M1: Liderança | N1: Prazo | O1: Data Conclusão Real | P1: Status | Q1: Observações | R1: Indicador_Relacionado | S1: Ação_Proposta | T1: Base_GUT | U1: Column2 | V1: Column3 | W1: Column4 | X1: Column5 | Y1: Column6
A2: 1 | B2: 27 | C2: UCO | D2: Segurança | E2: SESMT | F2: Vestimentas ou calçados inadequados para as atividades. Atendimento parcial informado. | G2: Não | H2: 3 | I2: 3 | J2: 3 | K2: 27 | L2: Baixa | M2: A confirmar | N2: 45603 | O2: 45603 | P2: Concluído | Q2: Tratativa informada: Sim | R2: Segurança das instalações | S2: Reforçar a orientação sobre vestimentas e calçados e acompanhar a adesão. | T2: Modelo: ação 175 (linha 176)
A3: 2 | B3: 45573 | C3: UCO | D3: Segurança | E3: SESMT | F3: Uso de adornos durante as atividades. Atendimento parcial informado. | G3: Não | H3: 3 | I3: 3 | J3: 3 | K3: 27 | L3: Baixa | M3: A confirmar | N3: 45603 | O3: 45603 | P3: Concluído | Q3: Tratativa informada: Sim | R3: Segurança das instalações | S3: Orientar a equipe sobre a padronização de adornos e verificar a adesão. | T3: Modelo: ação 175 (linha 176)
A4: 3 | B4: 45573 | C4: UCO | D4: Segurança contra Incêndio | E4: SESMT | F4: Ausência informada de detectores de fumaça. | G4: Não | H4: 3 | I4: 3 | J4: 3 | K4: 27 | L4: Baixa | M4: A confirmar | N4: 45603 | O4: 45603 | P4: Concluído | Q4: Avaliar a aplicabilidade ao local antes de confirmar a não conformidade. | R4: Segurança contra incêndio | S4: Solicitar avaliação do SESMT sobre cobertura e necessidade de detectores. | T4: Modelo: ação 176 (linha 177) | U4: Concluído | V4: Tratativa informada: Sim | W4: Segurança das instalações | X4: Reforçar a orientação sobre vestimentas e calçados e acompanhar a adesão. | Y4: Modelo: ação 175 (linha 176)
A5: 4 | B5: 45573 | C5: UCO | D5: Segurança contra Incêndio | E5: SESMT | F5: Mapeamento da rota de fuga não disponível. | G5: Não | H5: 3 | I5: 3 | J5: 3 | K5: 27 | L5: Baixa | M5: A confirmar | N5: 45603 | O5: 45603 | P5: Concluído | Q5: Tratativa informada: Sim | R5: Segurança contra incêndio | S5: Solicitar atualização ou disponibilização do mapeamento da rota de fuga. | T5: Modelo: ação 212 (linha 213) | U5: Concluído | V5: Tratativa informada: Sim | W5: Segurança das instalações | X5: Orientar a equipe sobre a padronização de adornos e verificar a adesão. | Y5: Modelo: ação 175 (linha 176)
A6: 5 | B6: 45573 | C6: UCO | D6: Segurança contra Incêndio | E6: SESMT | F6: Equipe sem conhecimento completo da rota de fuga. | G6: Não | H6: 3 | I6: 3 | J6: 3 | K6: 27 | L6: Baixa | M6: A confirmar | N6: 45603 | O6: 45603 | P6: Concluído | Q6: Tratativa informada: Sim | R6: Segurança contra incêndio | S6: Orientar a equipe sobre a rota de fuga e verificar a compreensão. | T6: Modelo: ação 212 (linha 213) | U6: Concluído | V6: Avaliar a aplicabilidade ao local antes de confirmar a não conformidade. | W6: Segurança contra incêndio | X6: Solicitar avaliação do SESMT sobre cobertura e necessidade de detectores. | Y6: Modelo: ação 176 (linha 177)
A7: 6 | B7: 45573 | C7: UCO | D7: Segurança contra Incêndio | E7: SESMT | F7: Ausência informada de brigadistas no momento da inspeção. | G7: Não | L7: Pendente de avaliação | M7: A confirmar | N7: 45603 | O7: 45603 | P7: Concluído | Q7: Avaliar a aplicabilidade ao local antes de confirmar a não conformidade. Sem exemplo suficientemente equivalente no modelo para atribuir as três notas GUT. | R7: Segurança contra incêndio | S7: Solicitar ao SESMT avaliação da cobertura da brigada para o setor e horário. | T7: Sem referência equivalente no modelo | U7: Concluído | V7: Tratativa informada: Sim | W7: Segurança contra incêndio | X7: Solicitar atualização ou disponibilização do mapeamento da rota de fuga. | Y7: Modelo: ação 212 (linha 213)
A8: 7 | B8: 45573 | C8: UCO | D8: Sistemas Utilitários | E8: Manutenção | F8: Presença de benjamim ou extensão elétrica. | G8: Não | H8: 3 | I8: 3 | J8: 3 | K8: 27 | L8: Baixa | M8: A confirmar | N8: 45603 | O8: 45603 | P8: Concluído | Q8: Tratativa informada: Sim | R8: Segurança elétrica | S8: Solicitar avaliação e regularização das conexões elétricas. | T8: Modelo: ação 214 (linha 215) | U8: Concluído | V8: Tratativa informada: Sim | W8: Segurança contra incêndio | X8: Orientar a equipe sobre a rota de fuga e verificar a compreensão. | Y8: Modelo: ação 212 (linha 213)
A9: 8 | B9: 45573 | C9: UCO | D9: Equipamento Médico | E9: Manutenção | F9: Equipamento elétrico sem validação da engenharia. | G9: Não | H9: 3 | I9: 4 | J9: 3 | K9: 36 | L9: Moderada | M9: A confirmar | N9: 45603 | O9: 45603 | P9: Concluído | Q9: Tratativa informada: Sim | R9: Segurança elétrica | S9: Retirar o equipamento do uso até avaliação pela área responsável. | T9: Modelo: ação 123 (linha 124) | U9: Concluído | V9: Avaliar a aplicabilidade ao local antes de confirmar a não conformidade. Sem exemplo suficientemente equivalente no modelo para atribuir as três notas GUT. | W9: Segurança contra incêndio | X9: Solicitar ao SESMT avaliação da cobertura da brigada para o setor e horário. | Y9: Sem referência equivalente no modelo
A10: 9 | B10: 45573 | C10: UCO | D10: Segurança contra Incêndio | E10: SESMT | F10: Ausência de sinalização de limite de altura para armazenamento. | G10: Não | H10: 3 | I10: 3 | J10: 3 | K10: 27 | L10: Baixa | M10: A confirmar | N10: 45603 | O10: 45603 | P10: Concluído | Q10: Avaliar a aplicabilidade ao local antes de confirmar a não conformidade. Tratativa informada: Sim | R10: Segurança contra incêndio | S10: Solicitar definição e sinalização do limite de altura aplicável. | T10: Modelo: ação 179 (linha 180) | U10: Concluído | V10: Tratativa informada: Sim | W10: Segurança elétrica | X10: Solicitar avaliação e regularização das conexões elétricas. | Y10: Modelo: ação 214 (linha 215)
A11: 10 | B11: 45573 | C11: UCO | D11: Segurança contra Incêndio | E11: SESMT | F11: Itens armazenados acima do limite de altura. | G11: Não | H11: 3 | I11: 4 | J11: 3 | K11: 36 | L11: Moderada | M11: A confirmar | N11: 45603 | O11: 45603 | P11: Concluído | Q11: Tratativa informada: Sim | R11: Segurança contra incêndio | S11: Reorganizar os itens respeitando o limite de altura. | T11: Modelo: ação 159 (linha 160) | U11: Concluído | V11: Tratativa informada: Sim | W11: Segurança elétrica | X11: Retirar o equipamento do uso até avaliação pela área responsável. | Y11: Modelo: ação 123 (linha 124)
A12: 11 | B12: 45573 | C12: UCO | D12: Materiais e Resíduos Perigosos | E12: SESMT | F12: Identificação incompleta ou ausente no coletor de perfurocortantes. | G12: Não | H12: 3 | I12: 3 | J12: 3 | K12: 27 | L12: Baixa | M12: A confirmar | N12: 45603 | O12: 45603 | P12: Concluído | Q12: Tratativa informada: Sim | R12: Materiais e resíduos perigosos | S12: Regularizar a identificação dos coletores e orientar a equipe. | T12: Modelo: ação 204 (linha 205) | U12: Concluído | V12: Avaliar a aplicabilidade ao local antes de confirmar a não conformidade. Tratativa informada: Sim | W12: Segurança contra incêndio | X12: Solicitar definição e sinalização do limite de altura aplicável. | Y12: Modelo: ação 179 (linha 180)
A13: 12 | B13: 45573 | C13: UCO | D13: Materiais e Resíduos Perigosos | E13: SESMT | F13: Suporte de coletor de perfurocortantes em altura inadequada. Atendimento parcial informado. | G13: Não | H13: 2 | I13: 3 | J13: 3 | K13: 18 | L13: Baixa | M13: A confirmar | N13: 45603 | O13: 45603 | P13: Concluído | Q13: Tratativa informada: Sim | R13: Materiais e resíduos perigosos | S13: Solicitar avaliação e adequação do suporte do coletor. | T13: Modelo: ação 114 (linha 115) | U13: Concluído | V13: Tratativa informada: Sim | W13: Segurança contra incêndio | X13: Reorganizar os itens respeitando o limite de altura. | Y13: Modelo: ação 159 (linha 160)
A14: 13 | B14: 45573 | C14: UCO | D14: Sistemas Utilitários | E14: Manutenção | F14: Inadequação nos espelhos de tomadas, interruptores ou pontos de rede. Atendimento parcial informado. | G14: Não | H14: 3 | I14: 3 | J14: 3 | K14: 27 | L14: Baixa | M14: A confirmar | N14: 45603 | O14: 45603 | P14: Concluído | Q14: Tratativa informada: Não | R14: Segurança elétrica | S14: Abrir ou acompanhar OS para corrigir os espelhos indicados. | T14: Modelo: ação 305 (linha 306) | U14: Concluído | V14: Tratativa informada: Sim | W14: Materiais e resíduos perigosos | X14: Regularizar a identificação dos coletores e orientar a equipe. | Y14: Modelo: ação 204 (linha 205)
A15: 14 | B15: 45573 | C15: UCO | D15: Segurança | E15: CCIH | F15: Avisos sem proteção adequada para higienização. Atendimento parcial informado. | G15: Não | H15: 2 | I15: 3 | J15: 3 | K15: 18 | L15: Baixa | M15: A confirmar | N15: 45603 | O15: 45603 | P15: Concluído | Q15: Tratativa informada: Sim | R15: Controle de infecção e saneamento | S15: Adequar a proteção e a fixação dos avisos. | T15: Modelo: ação 110 (linha 111) | U15: Concluído | V15: Tratativa informada: Sim | W15: Materiais e resíduos perigosos | X15: Solicitar avaliação e adequação do suporte do coletor. | Y15: Modelo: ação 114 (linha 115)
A16: 15 | B16: 45573 | C16: UCO | D16: Segurança | E16: Manutenção | F16: Parede com integridade ou conservação inadequada. | G16: Não | H16: 3 | I16: 3 | J16: 3 | K16: 27 | L16: Baixa | M16: A confirmar | N16: 45603 | O16: 45603 | P16: Concluído | Q16: Tratativa informada: Não | R16: Infraestrutura predial | S16: Avaliar e reparar as superfícies e a origem dos danos. | T16: Modelo: ação 241 (linha 242) | U16: Concluído | V16: Tratativa informada: Não | W16: Segurança elétrica | X16: Abrir ou acompanhar OS para corrigir os espelhos indicados. | Y16: Modelo: ação 305 (linha 306)
A17: 16 | B17: 45573 | C17: UCO | D17: Segurança | E17: Hotelaria | F17: Mobiliário com rasgo ou defeito. Atendimento parcial informado. | G17: Não | H17: 3 | I17: 3 | J17: 3 | K17: 27 | L17: Baixa | M17: A confirmar | N17: 45603 | O17: 45603 | P17: Concluído | Q17: Tratativa informada: Sim | R17: Segurança das instalações | S17: Solicitar reparo ou substituição do mobiliário indicado. | T17: Modelo: ação 140 (linha 141) | U17: Concluído | V17: Tratativa informada: Sim | W17: Controle de infecção e saneamento | X17: Adequar a proteção e a fixação dos avisos. | Y17: Modelo: ação 110 (linha 111)
A18: 17 | B18: 45573 | C18: UCO | D18: Segurança | E18: Hotelaria | F18: Porta-copos ou dispenser com integridade ou funcionamento inadequado. Atendimento parcial informado. | G18: Não | H18: 3 | I18: 4 | J18: 3 | K18: 36 | L18: Moderada | M18: A confirmar | N18: 45603 | O18: 45603 | P18: Concluído | Q18: Tratativa informada: Não | R18: Controle de infecção e saneamento | S18: Solicitar reparo ou substituição dos suportes e dispensers indicados. | T18: Modelo: ação 173 (linha 174) | U18: Concluído | V18: Tratativa informada: Não | W18: Infraestrutura predial | X18: Avaliar e reparar as superfícies e a origem dos danos. | Y18: Modelo: ação 241 (linha 242)
A19: 18 | B19: 45573 | C19: UCO | D19: Segurança | E19: Hotelaria | F19: Área com limpeza visual inadequada. Atendimento parcial informado. | G19: Não | H19: 3 | I19: 4 | J19: 3 | K19: 36 | L19: Moderada | M19: A confirmar | N19: 45603 | O19: 45603 | P19: Concluído | Q19: Tratativa informada: Não | R19: Limpeza/conservação | S19: Providenciar limpeza e revisar a rotina de higienização. | T19: Modelo: ação 139 (linha 140) | U19: Concluído | V19: Tratativa informada: Sim | W19: Segurança das instalações | X19: Solicitar reparo ou substituição do mobiliário indicado. | Y19: Modelo: ação 140 (linha 141)
... A23: 22 | B23: 45580 | C23: 2D | D23: Segurança contra Incêndio | E23: SESMT | F23: Mapeamento da rota de fuga não disponível. | G23: Não | H23: 3 | I23: 3 | J23: 3 | K23: 27 | L23: Baixa | M23: A confirmar | N23: 45610 | O23: 45610 | P23: Concluído | Q23: Tratativa informada: Sim | R23: Segurança contra incêndio | S23: Solicitar atualização ou disponibilização do mapeamento da rota de fuga. | T23: Modelo: ação 212 (linha 213) | U23: Concluído | V23: Tratativa informada: Sim | W23: Segurança das instalações | X23: Reforçar a orientação sobre vestimentas e calçados e acompanhar a adesão. | Y23: Modelo: ação 175 (linha 176)
A24: 23 | B24: 45580 | C24: 2D | D24: Segurança contra Incêndio | E24: SESMT | F24: Ausência informada de brigadistas no momento da inspeção. | G24: Não | L24: Pendente de avaliação | M24: A confirmar | N24: 45610 | O24: 45610 | P24: Concluído | Q24: Avaliar a aplicabilidade ao local antes de confirmar a não conformidade. Sem exemplo suficientemente equivalente no modelo para atribuir as três notas GUT. | R24: Segurança contra incêndio | S24: Solicitar ao SESMT avaliação da cobertura da brigada para o setor e horário. | T24: Sem referência equivalente no modelo | U24: Concluído | V24: Tratativa informada: Sim | W24: Segurança elétrica | X24: Desobstruir os painéis e manter o acesso livre. | Y24: Modelo: ação 196 (linha 197)
A25: 24 | B25: 45580 | C25: 2D | D25: Segurança contra Incêndio | E25: SESMT | F25: Ausência de sinalização de limite de altura para armazenamento. | G25: Não | H25: 3 | I25: 3 | J25: 3 | K25: 27 | L25: Baixa | M25: A confirmar | N25: 45610 | O25: 45610 | P25: Concluído | Q25: Avaliar a aplicabilidade ao local antes de confirmar a não conformidade. Tratativa informada: Sim | R25: Segurança contra incêndio | S25: Solicitar definição e sinalização do limite de altura aplicável. | T25: Modelo: ação 179 (linha 180) | U25: Concluído | V25: Tratativa informada: Sim | W25: Segurança contra incêndio | X25: Solicitar atualização ou disponibilização do mapeamento da rota de fuga. | Y25: Modelo: ação 212 (linha 213)
A26: 25 | B26: 45580 | C26: 2D | D26: Segurança contra Incêndio | E26: SESMT | F26: Itens armazenados acima do limite de altura. Atendimento parcial informado. | G26: Não | H26: 3 | I26: 4 | J26: 3 | K26: 36 | L26: Moderada | M26: A confirmar | N26: 45610 | O26: 45610 | P26: Concluído | Q26: Tratativa informada: Sim | R26: Segurança contra incêndio | S26: Reorganizar os itens respeitando o limite de altura. | T26: Modelo: ação 159 (linha 160) | U26: Concluído | V26: Avaliar a aplicabilidade ao local antes de confirmar a não conformidade. Sem exemplo suficientemente equivalente no modelo para atribuir as três notas GUT. | W26: Segurança contra incêndio | X26: Solicitar ao SESMT avaliação da cobertura da brigada para o setor e horário. | Y26: Sem referência equivalente no modelo
A27: 26 | B27: 45580 | C27: 2D | D27: Materiais e Resíduos Perigosos | E27: SESMT | F27: Identificação incompleta ou ausente no coletor de perfurocortantes. Atendimento parcial informado. | G27: Não | H27: 3 | I27: 3 | J27: 3 | K27: 27 | L27: Baixa | M27: A confirmar | N27: 45610 | O27: 45610 | P27: Concluído | Q27: Tratativa informada: Sim | R27: Materiais e resíduos perigosos | S27: Regularizar a identificação dos coletores e orientar a equipe. | T27: Modelo: ação 204 (linha 205) | U27: Concluído | V27: Avaliar a aplicabilidade ao local antes de confirmar a não conformidade. Tratativa informada: Sim | W27: Segurança contra incêndio | X27: Solicitar definição e sinalização do limite de altura aplicável. | Y27: Modelo: ação 179 (linha 180)
A28: 27 | B28: 45580 | C28: 2D | D28: Sistemas Utilitários | E28: Manutenção | F28: Identificação de voltagem ausente ou incompleta nas tomadas. Atendimento parcial informado. | G28: Não | H28: 3 | I28: 3 | J28: 3 | K28: 27 | L28: Baixa | M28: A confirmar | N28: 45610 | O28: 45610 | P28: Concluído | R28: Segurança elétrica | S28: Providenciar identificação da voltagem após verificação técnica. | T28: Modelo: ação 240 (linha 241) | U28: Concluído | V28: Tratativa informada: Sim | W28: Segurança contra incêndio | X28: Reorganizar os itens respeitando o limite de altura. | Y28: Modelo: ação 159 (linha 160)
A29: 28 | B29: 45580 | C29: 2D | D29: Sistemas Utilitários | E29: Manutenção | F29: Torneira assistencial que exige o uso das mãos para fechamento. | G29: Não | H29: 3 | I29: 4 | J29: 3 | K29: 36 | L29: Moderada | M29: A confirmar | N29: 45610 | O29: 45610 | P29: Concluído | Q29: Tratativa informada: Não | R29: Controle de infecção e saneamento | S29: Solicitar adequação das torneiras ao modelo previsto para o uso. | T29: Modelo: ação 316 (linha 317) | U29: Concluído | V29: Tratativa informada: Sim | W29: Materiais e resíduos perigosos | X29: Regularizar a identificação dos coletores e orientar a equipe. | Y29: Modelo: ação 204 (linha 205)
A30: 29 | B30: 45580 | C30: 2D | D30: Segurança | E30: Manutenção | F30: Barreiras ou trancas de janelas inadequadas. | G30: Não | H30: 3 | I30: 3 | J30: 3 | K30: 27 | L30: Baixa | M30: A confirmar | N30: 45610 | O30: 45610 | P30: Concluído | Q30: Tratativa informada: Não | R30: Controle de infecção e saneamento | S30: Solicitar adequação das telas ou trancas das janelas. | T30: Modelo: ação 310 (linha 311) | U30: Concluído | W30: Segurança elétrica | X30: Providenciar identificação da voltagem após verificação técnica. | Y30: Modelo: ação 240 (linha 241)
A31: 30 | B31: 45580 | C31: 2D | D31: Materiais e Resíduos Perigosos | E31: CCIH | F31: Resíduo ou outro item disposto diretamente no chão. | G31: Não | H31: 3 | I31: 3 | J31: 3 | K31: 27 | L31: Baixa | M31: A confirmar | N31: 45610 | O31: 45610 | P31: Concluído | Q31: Tratativa informada: Sim | R31: Controle de infecção e saneamento | S31: Retirar os itens do chão e adequar o acondicionamento. | T31: Modelo: ação 172 (linha 173) | U31: Concluído | V31: Tratativa informada: Não | W31: Controle de infecção e saneamento | X31: Solicitar adequação das torneiras ao modelo previsto para o uso. | Y31: Modelo: ação 316 (linha 317)
A32: 31 | B32: 45580 | C32: 2D | D32: Segurança | E32: Manutenção | F32: Parede com integridade ou conservação inadequada. | G32: Não | H32: 3 | I32: 3 | J32: 3 | K32: 27 | L32: Baixa | M32: A confirmar | N32: 45610 | O32: 45610 | P32: Concluído | Q32: Tratativa informada: Não | R32: Infraestrutura predial | S32: Avaliar e reparar as superfícies e a origem dos danos. | T32: Modelo: ação 241 (linha 242) | U32: Concluído | V32: Tratativa informada: Não | W32: Controle de infecção e saneamento | X32: Solicitar adequação das telas ou trancas das janelas. | Y32: Modelo: ação 310 (linha 311)
A33: 32 | B33: 45580 | C33: 2D | D33: Sistemas Utilitários | E33: Manutenção | F33: Climatização com problema de funcionamento, sujidade ou vazamento. | G33: Não | H33: 3 | I33: 4 | J33: 3 | K33: 36 | L33: Moderada | M33: A confirmar | N33: 45610 | O33: 45610 | P33: Concluído | Q33: Tratativa informada: Não | R33: Climatização | S33: Solicitar avaliação, limpeza ou reparo do sistema de climatização. | T33: Modelo: ação 112 (linha 113) | U33: Concluído | V33: Tratativa informada: Sim | W33: Controle de infecção e saneamento | X33: Retirar os itens do chão e adequar o acondicionamento. | Y33: Modelo: ação 172 (linha 173)
A34: 33 | B34: 45580 | C34: 2D | D34: Segurança | E34: Hotelaria | F34: Mobiliário com rasgo ou defeito. Atendimento parcial informado. | G34: Não | H34: 3 | I34: 3 | J34: 3 | K34: 27 | L34: Baixa | M34: A confirmar | N34: 45610 | O34: 45610 | P34: Concluído | Q34: Tratativa informada: Não | R34: Segurança das instalações | S34: Solicitar reparo ou substituição do mobiliário indicado. | T34: Modelo: ação 140 (linha 141) | U34: Concluído | V34: Tratativa informada: Não | W34: Infraestrutura predial | X34: Avaliar e reparar as superfícies e a origem dos danos. | Y34: Modelo: ação 241 (linha 242)
A35: 34 | B35: 45580 | C35: 2D | D35: Segurança | E35: Manutenção | F35: Bate-maca com integridade inadequada. Atendimento parcial informado. | G35: Não | H35: 3 | I35: 3 | J35: 3 | K35: 27 | L35: Baixa | M35: A confirmar | N35: 45610 | O35: 45610 | P35: Concluído | Q35: Tratativa informada: Não | R35: Infraestrutura predial | S35: Solicitar reparo ou fixação do bate-maca. | T35: Modelo: ação 301 (linha 302) | U35: Concluído | V35: Tratativa informada: Não | W35: Climatização | X35: Solicitar avaliação, limpeza ou reparo do sistema de climatização. | Y35: Modelo: ação 112 (linha 113)
A36: 35 | B36: 45580 | C36: 2D | D36: Segurança | E36: Manutenção | F36: Cantoneira ausente ou sem integridade adequada. | G36: Não | H36: 3 | I36: 3 | J36: 3 | K36: 27 | L36: Baixa | M36: A confirmar | N36: 45610 | O36: 45610 | P36: Concluído | Q36: Tratativa informada: Não | R36: Infraestrutura predial | S36: Solicitar instalação, reparo ou fixação das cantoneiras. | T36: Modelo: ação 307 (linha 308) | U36: Concluído | V36: Tratativa informada: Não | W36: Segurança das instalações | X36: Solicitar reparo ou substituição do mobiliário indicado. | Y36: Modelo: ação 140 (linha 141)
A37: 36 | B37: 45580 | C37: 2D | D37: Segurança | E37: Hotelaria | F37: Área com limpeza visual inadequada. | G37: Não | H37: 3 | I37: 4 | J37: 3 | K37: 36 | L37: Moderada | M37: A confirmar | N37: 45610 | O37: 45610 | P37: Concluído | Q37: Tratativa informada: Sim | R37: Limpeza/conservação | S37: Providenciar limpeza e revisar a rotina de higienização. | T37: Modelo: ação 139 (linha 140) | U37: Concluído | V37: Tratativa informada: Não | W37: Infraestrutura predial | X37: Solicitar reparo ou fixação do bate-maca. | Y37: Modelo: ação 301 (linha 302)
A38: 37 | B38: 45587 | C38: 2ºC | D38: Segurança | E38: SESMT | F38: Vestimentas ou calçados inadequados para as atividades. Atendimento parcial informado. | G38: Não | H38: 3 | I38: 3 | J38: 3 | K38: 27 | L38: Baixa | M38: A confirmar | N38: 45617 | O38: 45610 | P38: Concluído | Q38: Tratativa informada: Sim | R38: Segurança das instalações | S38: Reforçar a orientação sobre vestimentas e calçados e acompanhar a adesão. | T38: Modelo: ação 175 (linha 176) | U38: Concluído | V38: Tratativa informada: Não | W38: Infraestrutura predial | X38: Solicitar instalação, reparo ou fixação das cantoneiras. | Y38: Modelo: ação 307 (linha 308)
A39: 38 | B39: 45587 | C39: 2ºC | D39: Sistemas Utilitários | E39: Área assistencial/administrativa | F39: Obstrução do acesso a painéis elétricos. Atendimento parcial informado. | G39: Não | H39: 3 | I39: 4 | J39: 3 | K39: 36 | L39: Moderada | M39: A confirmar | N39: 45617 | O39: 45617 | P39: Concluído | Q39: Tratativa informada: Sim | R39: Segurança elétrica | S39: Desobstruir os painéis e manter o acesso livre. | T39: Modelo: ação 196 (linha 197) | U39: Concluído | V39: Tratativa informada: Sim | W39: Limpeza/conservação | X39: Providenciar limpeza e revisar a rotina de higienização. | Y39: Modelo: ação 139 (linha 140)
A40: 39 | B40: 45587 | C40: 2ºC | D40: Segurança contra Incêndio | E40: SESMT | F40: Ausência informada de detectores de fumaça. | G40: Não | H40: 3 | I40: 3 | J40: 3 | K40: 27 | L40: Baixa | M40: A confirmar | N40: 45617 | O40: 45617 | P40: Concluído | Q40: Avaliar a aplicabilidade ao local antes de confirmar a não conformidade. | R40: Segurança contra incêndio | S40: Solicitar avaliação do SESMT sobre cobertura e necessidade de detectores. | T40: Modelo: ação 176 (linha 177) | U40: Concluído | V40: Tratativa informada: Sim | W40: Segurança das instalações | X40: Reforçar a orientação sobre vestimentas e calçados e acompanhar a adesão. | Y40: Modelo: ação 175 (linha 176)
A41: 40 | B41: 45587 | C41: 2ºC | D41: Segurança contra Incêndio | E41: SESMT | F41: Mapeamento da rota de fuga não disponível. | G41: Não | H41: 3 | I41: 3 | J41: 3 | K41: 27 | L41: Baixa | M41: A confirmar | N41: 45617 | O41: 45617 | P41: Concluído | Q41: Tratativa informada: Sim | R41: Segurança contra incêndio | S41: Solicitar atualização ou disponibilização do mapeamento da rota de fuga. | T41: Modelo: ação 212 (linha 213) | U41: Concluído | V41: Tratativa informada: Sim | W41: Segurança elétrica | X41: Desobstruir os painéis e manter o acesso livre. | Y41: Modelo: ação 196 (linha 197)
A42: 41 | B42: 45587 | C42: 2ºC | D42: Segurança contra Incêndio | E42: SESMT | F42: Equipe sem conhecimento completo da rota de fuga. | G42: Não | H42: 3 | I42: 3 | J42: 3 | K42: 27 | L42: Baixa | M42: A confirmar | N42: 45617 | O42: 45617 | P42: Concluído | Q42: Tratativa informada: Sim | R42: Segurança contra incêndio | S42: Orientar a equipe sobre a rota de fuga e verificar a compreensão. | T42: Modelo: ação 212 (linha 213) | U42: Concluído | V42: Avaliar a aplicabilidade ao local antes de confirmar a não conformidade. | W42: Segurança contra incêndio | X42: Solicitar avaliação do SESMT sobre cobertura e necessidade de detectores. | Y42: Modelo: ação 176 (linha 177)
A43: 42 | B43: 45587 | C43: 2ºC | D43: Segurança contra Incêndio | E43: SESMT | F43: Ausência informada de brigadistas no momento da inspeção. | G43: Não | L43: Pendente de avaliação | M43: A confirmar | N43: 45617 | O43: 45617 | P43: Concluído | Q43: Avaliar a aplicabilidade ao local antes de confirmar a não conformidade. Sem exemplo suficientemente equivalente no modelo para atribuir as três notas GUT. | R43: Segurança contra incêndio | S43: Solicitar ao SESMT avaliação da cobertura da brigada para o setor e horário. | T43: Sem referência equivalente no modelo | U43: Concluído | V43: Tratativa informada: Sim | W43: Segurança contra incêndio | X43: Solicitar atualização ou disponibilização do mapeamento da rota de fuga. | Y43: Modelo: ação 212 (linha 213)
...

Sheet Interações Rounds
A1: Categoria' | B1: Subcategoria | C1: Mês | D1: Número Mês | E1: Quantidade
A2: Infra e Hotelaria | B2: Ar Condicionado | C2: Janeiro | D2: 1 | E2: 6
A3: Infra e Hotelaria | B3: Ar Condicionado | C3: Fevereiro | D3: 2 | E3: 6
A4: Infra e Hotelaria | B4: Ar Condicionado | C4: Março | D4: 3 | E4: 20
A5: Infra e Hotelaria | B5: Ar Condicionado | C5: Abril | D5: 4 | E5: 11
A6: Infra e Hotelaria | B6: Ar Condicionado | C6: Maio | D6: 5 | E6: 8
A7: Infra e Hotelaria | B7: Ar Condicionado | C7: Junho | D7: 6 | E7: 1
A8: Infra e Hotelaria | B8: Ar Condicionado | C8: Julho | D8: 7 | E8: 0
A9: Infra e Hotelaria | B9: Ar Condicionado | C9: Agosto | D9: 8 | E9: 0
A10: Infra e Hotelaria | B10: Ar Condicionado | C10: Setembro | D10: 9 | E10: 0
A11: Infra e Hotelaria | B11: Ar Condicionado | C11: Outubro | D11: 10 | E11: 0
A12: Infra e Hotelaria | B12: Ar Condicionado | C12: Novembro | D12: 11 | E12: 2
A13: Infra e Hotelaria | B13: Ar Condicionado | C13: Dezembro | D13: 12 | E13: 2
... A193: Assistencial | B193: Problema/Demora alimentação | C193: Dezembro | D193: 12 | E193: 0
A194: Assistencial | C194: Janeiro | D194: 1 | E194: 0
A195: Assistencial | C195: Fevereiro | D195: 2 | E195: 0
A196: Assistencial | C196: Março | D196: 3 | E196: 0
A197: Assistencial | C197: Abril | D197: 4 | E197: 0
A198: Assistencial | C198: Maio | D198: 5 | E198: 0
A199: Assistencial | B199: Problema Solicitações Q24 | C199: Junho | D199: 6 | E199: 1
A200: Assistencial | B200: Problema Solicitações Q24 | C200: Julho | D200: 7 | E200: 0
A201: Assistencial | B201: Problema Solicitações Q24 | C201: Agosto | D201: 8 | E201: 0
A202: Assistencial | B202: Problema Solicitações Q24 | C202: Setembro | D202: 9 | E202: 0
A203: Assistencial | B203: Problema Solicitações Q24 | C203: Outubro | D203: 10 | E203: 0
A204: Assistencial | B204: Problema Solicitações Q24 | C204: Novembro | D204: 11 | E204: 0
A205: Assistencial | B205: Problema Solicitações Q24 | C205: Dezembro | D205: 12 | E205: 0
A206: Assistencial | B206: Demora Medicação | C206: Janeiro | D206: 1 | E206: 0
A207: Assistencial | B207: Demora Medicação | C207: Fevereiro | D207: 2 | E207: 0
A208: Assistencial | B208: Demora Medicação | C208: Março | D208: 3 | E208: 0
A209: Assistencial | B209: Demora Medicação | C209: Abril | D209: 4 | E209: 0
A210: Assistencial | B210: Demora Medicação | C210: Maio | D210: 5 | E210: 0
... A709: Sistemas Informações | B709: Dúvidas Solicitação de Prontuário | C709: Dezembro | D709: 12 | E709: 0

Sheet Rounds
A1: Responsáveis | B1: Setores | C1: Ano | D1: Meses | E1: Realizados | F1: Previstos | G1: Pendentes | H1: % de Realizados
A2: Melissa Cogo e Carmela | B2: 1°D | C2: 2026 | D2: Janeiro | E2: 12 | F2: 12 | G2: =Rounds!$F2-Rounds!$E2 | H2: =Rounds!$E2/Rounds!$F2
A3: Melissa Cogo e Carmela | B3: 1°D | C3: 2026 | D3: Fevereiro | E3: 12 | F3: 12 | G3: =Rounds!$F3-Rounds!$E3 | H3: =Rounds!$E3/Rounds!$F3
A4: Melissa Cogo e Carmela | B4: 1°D | C4: 2026 | D4: Março | E4: 12 | F4: 12 | G4: =Rounds!$F4-Rounds!$E4 | H4: =Rounds!$E4/Rounds!$F4
A5: Melissa Cogo e Carmela | B5: 1°D | C5: 2026 | D5: Abril | E5: 15 | F5: 15 | G5: =Rounds!$F5-Rounds!$E5 | H5: =Rounds!$E5/Rounds!$F5
A6: Melissa Cogo e Carmela | B6: 1°D | C6: 2026 | D6: Maio | E6: 12 | F6: 12 | G6: =Rounds!$F6-Rounds!$E6 | H6: =Rounds!$E6/Rounds!$F6
A7: Melissa Cogo e Carmela | B7: 1°D | C7: 2026 | D7: Junho | E7: 12 | F7: 12 | G7: =Rounds!$F7-Rounds!$E7 | H7: =Rounds!$E7/Rounds!$F7
A8: Melissa Cogo e Carmela | B8: 1°D | C8: 2026 | D8: Julho | E8: 15 | F8: 15 | G8: =Rounds!$F8-Rounds!$E8 | H8: =Table6[[#This Row],[Realizados]]/Table6[[#This Row],[Previstos]]
A9: Melissa Cogo e Carmela | B9: 1°D | C9: 2026 | D9: Agosto | E9: 12 | F9: 12 | G9: =Rounds!$F9-Rounds!$E9 | H9: 0
A10: Melissa Cogo e Carmela | B10: 1°D | C10: 2026 | D10: Setembro | E10: 15 | F10: 15 | G10: =Rounds!$F10-Rounds!$E10 | H10: =Table6[[#This Row],[Realizados]]/Table6[[#This Row],[Previstos]]
A11: Melissa Cogo e Carmela | B11: 1°D | C11: 2026 | D11: Outubro | E11: 0 | F11: 0 | G11: =Rounds!$F11-Rounds!$E11 | H11: 0
A12: Melissa Cogo e Carmela | B12: 1°D | C12: 2026 | D12: Novembro | E12: 0 | F12: 0 | G12: =Rounds!$F12-Rounds!$E12 | H12: 0
A13: Melissa Cogo e Carmela | B13: 1°D | C13: 2026 | D13: Dezembro | E13: 0 | F13: 0 | G13: =Rounds!$F13-Rounds!$E13 | H13: 0
A14: Danielle e Dr. Eduardo | B14: 2°C | C14: 2026 | D14: Janeiro | E14: 12 | F14: 12 | G14: =Rounds!$F14-Rounds!$E14 | H14: =Rounds!$E14/Rounds!$F14
A15: Danielle e Dr. Eduardo | B15: 2°C | C15: 2026 | D15: Fevereiro | E15: 12 | F15: 12 | G15: =Rounds!$F15-Rounds!$E15 | H15: =Rounds!$E15/Rounds!$F15
A16: Danielle e Dr. Eduardo | B16: 2°C | C16: 2026 | D16: Março | E16: 12 | F16: 12 | G16: =Rounds!$F16-Rounds!$E16 | H16: =Rounds!$E16/Rounds!$F16
A17: Danielle e Dr. Eduardo | B17: 2°C | C17: 2026 | D17: Abril | E17: 12 | F17: 15 | G17: =Rounds!$F17-Rounds!$E17 | H17: =Rounds!$E17/Rounds!$F17
A18: Danielle e Dr. Eduardo | B18: 2°C | C18: 2026 | D18: Maio | E18: 12 | F18: 12 | G18: =Rounds!$F18-Rounds!$E18 | H18: =Rounds!$E18/Rounds!$F18
A19: Danielle e Dr. Eduardo | B19: 2°C | C19: 2026 | D19: Junho | E19: 2 | F19: 12 | G19: =Rounds!$F19-Rounds!$E19 | H19: =Rounds!$E19/Rounds!$F19
A20: Danielle e Dr. Eduardo | B20: 2°C | C20: 2026 | D20: Julho | E20: 11 | F20: 14 | G20: =Rounds!$F20-Rounds!$E20 | H20: =Table6[[#This Row],[Realizados]]/Table6[[#This Row],[Previstos]]
A21: Danielle e Dr. Eduardo | B21: 2°C | C21: 2026 | D21: Agosto | E21: 12 | F21: 12 | G21: =Rounds!$F21-Rounds!$E21 | H21: 0
A22: Danielle e Dr. Eduardo | B22: 2°C | C22: 2026 | D22: Setembro | E22: 13 | F22: 15 | G22: =Rounds!$F22-Rounds!$E22 | H22: =Table6[[#This Row],[Realizados]]/Table6[[#This Row],[Previstos]]
A23: Danielle e Dr. Eduardo | B23: 2°C | C23: 2026 | D23: Outubro | E23: 0 | F23: 0 | G23: =Rounds!$F23-Rounds!$E23 | H23: 0
A24: Danielle e Dr. Eduardo | B24: 2°C | C24: 2026 | D24: Novembro | E24: 0 | F24: 0 | G24: =Rounds!$F24-Rounds!$E24 | H24: 0
A25: Danielle e Dr. Eduardo | B25: 2°C | C25: 2026 | D25: Dezembro | E25: 0 | F25: 0 | G25: =Rounds!$F25-Rounds!$E25 | H25: 0
A26: Dr. Giroto e Thiago | B26: 2°D | C26: 2026 | D26: Janeiro | E26: 4 | F26: 12 | G26: =Rounds!$F26-Rounds!$E26 | H26: =Rounds!$E26/Rounds!$F26
A27: Dr. Giroto e Thiago | B27: 2°D | C27: 2026 | D27: Fevereiro | E27: 11 | F27: 12 | G27: =Rounds!$F27-Rounds!$E27 | H27: =Rounds!$E27/Rounds!$F27
A28: Dr. Giroto e Thiago | B28: 2°D | C28: 2026 | D28: Março | E28: 8 | F28: 12 | G28: =Rounds!$F28-Rounds!$E28 | H28: =Rounds!$E28/Rounds!$F28
A29: Dr. Giroto e Thiago | B29: 2°D | C29: 2026 | D29: Abril | E29: 14 | F29: 15 | G29: =Rounds!$F29-Rounds!$E29 | H29: =Rounds!$E29/Rounds!$F29
A30: Dr. Giroto e Thiago | B30: 2°D | C30: 2026 | D30: Maio | E30: 9 | F30: 12 | G30: =Rounds!$F30-Rounds!$E30 | H30: =Rounds!$E30/Rounds!$F30
A31: Dr. Giroto e Thiago | B31: 2°D | C31: 2026 | D31: Junho | E31: 8 | F31: 12 | G31: =Rounds!$F31-Rounds!$E31 | H31: =Rounds!$E31/Rounds!$F31
A32: Dr. Giroto e Thiago | B32: 2°D | C32: 2026 | D32: Julho | E32: 10 | F32: 15 | G32: =Rounds!$F32-Rounds!$E32 | H32: =Table6[[#This Row],[Realizados]]/Table6[[#This Row],[Previstos]]
A33: Dr. Giroto e Thiago | B33: 2°D | C33: 2026 | D33: Agosto | E33: 10 | F33: 12 | G33: =Rounds!$F33-Rounds!$E33 | H33: 0
A34: Dr. Giroto e Thiago | B34: 2°D | C34: 2026 | D34: Setembro | E34: 9 | F34: 15 | G34: =Rounds!$F34-Rounds!$E34 | H34: =Table6[[#This Row],[Realizados]]/Table6[[#This Row],[Previstos]]
A35: Dr. Giroto e Thiago | B35: 2°D | C35: 2026 | D35: Outubro | E35: 0 | F35: 0 | G35: =Rounds!$F35-Rounds!$E35 | H35: 0
A36: Dr. Giroto e Thiago | B36: 2°D | C36: 2026 | D36: Novembro | E36: 0 | F36: 0 | G36: =Rounds!$F36-Rounds!$E36 | H36: 0
A37: Dr. Giroto e Thiago | B37: 2°D | C37: 2026 | D37: Dezembro | E37: 0 | F37: 0 | G37: =Rounds!$F37-Rounds!$E37 | H37: 0
A38: Lilian | B38: Semi 2 | C38: 2026 | D38: Janeiro | E38: 12 | F38: 12 | G38: =Rounds!$F38-Rounds!$E38 | H38: =Rounds!$E38/Rounds!$F38
A39: Lilian | B39: Semi 2 | C39: 2026 | D39: Fevereiro | E39: 12 | F39: 12 | G39: =Rounds!$F39-Rounds!$E39 | H39: =Rounds!$E39/Rounds!$F39
A40: Lilian | B40: Semi 2 | C40: 2026 | D40: Março | E40: 12 | F40: 12 | G40: =Rounds!$F40-Rounds!$E40 | H40: =Rounds!$E40/Rounds!$F40
...

Sheet Interações Round
A1: Mês | B1: Ano | C1: Categoria | D1: Interação | E1: Quartos | F1: Setor
A2: Janeiro | B2: 2026 | C2: Infra e Hotelaria | D2: Climatização | E2: Quarto 112 | F2: 1°D
A3: Janeiro | B3: 2026 | C3: Infra e Hotelaria | D3: Hotelaria/Rouparia | E3: Quarto 315 | F3: 3°D
A4: Janeiro | B4: 2026 | C4: Infra e Hotelaria | D4: Hotelaria/Rouparia | E4: Quarto 432 | F4: PED/UTI PED
A5: Janeiro | B5: 2026 | C5: Infra e Hotelaria | D5: Manutenção/Instalações | E5: Setor | F5: 1°D
A6: Janeiro | B6: 2026 | C6: Infra e Hotelaria | D6: Manutenção/Instalações | E6: Setor | F6: UTI NEO/8°D
A7: Janeiro | B7: 2026 | C7: Infra e Hotelaria | D7: Climatização | E7: Quarto 405 | F7: 4°D
A8: Janeiro | B8: 2026 | C8: Infra e Hotelaria | D8: Hotelaria/Rouparia | E8: Quarto 415 | F8: 4°D
A9: Janeiro | B9: 2026 | C9: Infra e Hotelaria | D9: Manutenção/Instalações | E9: Quarto 317 | F9: Semi 1
A10: Janeiro | B10: 2026 | C10: Infra e Hotelaria | D10: Manutenção/Instalações | E10: Setor | F10: 1°D
A11: Janeiro | B11: 2026 | C11: Infra e Hotelaria | D11: Engenharia Clínica | E11: Quarto 432 | F11: PED/UTI PED
A12: Janeiro | B12: 2026 | C12: Infra e Hotelaria | D12: Climatização | E12: Quarto 214 | F12: 2°D
A13: Janeiro | B13: 2026 | C13: Infra e Hotelaria | D13: Manutenção/Instalações | E13: Quarto 704 | F13: Maternidade
... A4056: Março | B4056: 2023 | C4056: Sistemas de Informação | D4056: Dispositivos Digitais | E4056: Setor | F4056: 1°D
A4057: Março | B4057: 2023 | C4057: Sistemas de Informação | D4057: Dispositivos Digitais | E4057: 203 | F4057: 2°D
A4058: Março | B4058: 2023 | C4058: Sistemas de Informação | D4058: Dispositivos Digitais | E4058: Setor | F4058: Centro Cirúrgico
A4059: Março | B4059: 2023 | C4059: Sistemas de Informação | D4059: Dispositivos Digitais | E4059: Agrupado na fonte — UTI | F4059: Não informado na fonte
A4060: Março | B4060: 2023 | C4060: Sistemas de Informação | D4060: Dispositivos Digitais | E4060: Agrupado na fonte — UTI | F4060: Não informado na fonte
A4061: Março | B4061: 2023 | C4061: Sistemas de Informação | D4061: Dispositivos Digitais | E4061: Paciente relata estar sem na acomodação | F4061: Não informado na fonte
A4062: Março | B4062: 2023 | C4062: Sistemas de Informação | D4062: Dispositivos Digitais | E4062: Posto enf 2ºD | F4062: Não informado na fonte
A4063: Abril | B4063: 2023 | C4063: Infra e Hotelaria | D4063: Manutenção/Instalações | E4063: Agrupado na fonte — UTI A | F4063: Não informado na fonte
A4064: Abril | B4064: 2023 | C4064: Infra e Hotelaria | D4064: Manutenção/Instalações | E4064: Agrupado na fonte — UTI A | F4064: Não informado na fonte
A4065: Abril | B4065: 2023 | C4065: Infra e Hotelaria | D4065: Manutenção/Instalações | E4065: Mater | F4065: Não informado na fonte
A4066: Abril | B4066: 2023 | C4066: Infra e Hotelaria | D4066: Engenharia Clínica | E4066: Setor | F4066: 3°D
A4067: Abril | B4067: 2023 | C4067: Infra e Hotelaria | D4067: Engenharia Clínica | E4067: Setor | F4067: Não informado na fonte
A4068: Abril | B4068: 2023 | C4068: Assistencial | D4068: Medicamentos/Farmácia | E4068: Setor | F4068: 2°D
A4069: Abril | B4069: 2023 | C4069: Assistencial | D4069: Medicamentos/Farmácia | E4069: Setor | F4069: Não informado na fonte
... A4071: Abril | B4071: 2023 | C4071: Sistemas de Informação | D4071: Sistemas/TI/Conectividade | E4071: Setor | F4071: Não informado na fonte
A4072: Maio | B4072: 2023 | C4072: Infra e Hotelaria | D4072: Manutenção/Instalações | E4072: 102 | F4072: 1°D
A4073: Maio | B4073: 2023 | C4073: Infra e Hotelaria | D4073: Manutenção/Instalações | E4073: Setor | F4073: UTI NEO/8°D
A4074: Maio | B4074: 2023 | C4074: Infra e Hotelaria | D4074: Manutenção/Instalações | E4074: Setor | F4074: UTI NEO/8°D
A4075: Maio | B4075: 2023 | C4075: Infra e Hotelaria | D4075: Manutenção/Instalações | E4075: Agrupado na fonte — UCO/3ºC/102/802 | F4075: Não informado na fonte
A4076: Maio | B4076: 2023 | C4076: Infra e Hotelaria | D4076: Manutenção/Instalações | E4076: Agrupado na fonte — UCO/3ºC/102/802 | F4076: Não informado na fonte
A4077: Maio | B4077: 2023 | C4077: Infra e Hotelaria | D4077: Manutenção/Instalações | E4077: Agrupado na fonte — UCO/3ºC/102/802 | F4077: Não informado na fonte
A4078: Maio | B4078: 2023 | C4078: Infra e Hotelaria | D4078: Manutenção/Instalações | E4078: Agrupado na fonte — UCO/3ºC/102/802 | F4078: Não informado na fonte
A4079: Maio | B4079: 2023 | C4079: Infra e Hotelaria | D4079: Manutenção/Instalações | E4079: Agrupado na fonte — UCO/3ºC/102/802 | F4079: Não informado na fonte
A4080: Maio | B4080: 2023 | C4080: Infra e Hotelaria | D4080: Manutenção/Instalações | E4080: Agrupado na fonte — UCO/3ºC/102/802 | F4080: Não informado na fonte
A4081: Maio | B4081: 2023 | C4081: Infra e Hotelaria | D4081: Manutenção/Instalações | E4081: Agrupado na fonte — UCO/3ºC/102/802 | F4081: Não informado na fonte
A4082: Maio | B4082: 2023 | C4082: Infra e Hotelaria | D4082: Manutenção/Instalações | E4082: Setor | F4082: Não informado na fonte
A4083: Maio | B4083: 2023 | C4083: Infra e Hotelaria | D4083: Hotelaria/Rouparia | E4083: 802 | F4083: Não informado na fonte
...

Sheet Planos de ação Huddle
A2: Ação | B2: Data_Registro | C2: Mês | D2: Ano | E2: Unidade | F2: Setor | G2: Categoria | H2: O_que_aconteceu | I2: Status | J2: Liderança | K2: Observação
A3: 1 | B3: 45518 | C3: Agosto | D3: 2024 | E3: HVC | F3: Operações | G3: Assistencial | H3: Avental - Qualidade | I3: Concluído | J3: Simone
A4: 2 | B4: 45518 | C4: Agosto | D4: 2024 | E4: HVC | F4: Laboratório | G4: Assistencial | H4: Hemoculturas - Atenção Global | I4: Concluído | J4: Não informado | K4: Risco de decisão clínica incorreta por erro de amostra ou comunicação.
A5: 3 | B5: 45518 | C5: Agosto | D5: 2024 | E5: HVC | F5: Operações / Enfermagem | G5: Sistemas de Informações | H5: Quality24 - Concierge: Adesão SLA | I5: Concluído | J5: Simone / Lilian | K5: Recorrência de baixa adesão, atraso e ausência de encerramento dos chamados.
A6: 4 | B6: 45518 | C6: Agosto | D6: 2024 | E6: HVC | F6: Operações | G6: Assistencial | H6: Nutrição - atraso dieta | I6: Concluído | J6: Simone | K6: Recorrência de atrasos e risco de dieta inadequada ao paciente.
A7: 5 | B7: 45518 | C7: Agosto | D7: 2024 | E7: HVC | F7: Operações | G7: Infra e Hotelaria | H7: Higiene CME | I7: Concluído | J7: Simone | K7: Risco de infecção e interrupção cirúrgica com recorrência e pendências abertas.
A8: 6 | B8: 45518 | C8: Agosto | D8: 2024 | E8: HVC | F8: Operações | G8: Infra e Hotelaria | H8: Higiene Noturno | I8: Concluído | J8: Simone | K8: Recorrência, pendências abertas e impacto na segurança e experiência.
A9: 7 | B9: 45518 | C9: Agosto | D9: 2024 | E9: HVC | F9: NSP | G9: Assistencial | H9: Falha na Identificação do Paciente PA | I9: Concluído | J9: Não informado | K9: Risco de evento grave, recorrência elevada e falhas em barreiras essenciais.
A10: 8 | B10: 45518 | C10: Agosto | D10: 2024 | E10: HVC | F10: NSP | G10: Assistencial | H10: Número de Punções alto/ FLEBITE | I10: Concluído | J10: Déborah | K10: Recorrência de flebite, perdas de acesso e extravasamentos.
A11: 9 | B11: 45518 | C11: Agosto | D11: 2024 | E11: HVC | F11: Enfermagem | G11: Assistencial | H11: Prótese com lateralidade errada | I11: Concluído | J11: Não informado | K11: Risco de evento grave, recorrência elevada e falhas em barreiras essenciais.
A12: 10 | B12: 45518 | C12: Agosto | D12: 2024 | E12: HVC | F12: Operações | G12: Infra e Hotelaria | H12: Elevador parou com paciente entubado | I12: Concluído | J12: Januário
A13: 11 | B13: 45518 | C13: Agosto | D13: 2024 | E13: HVC | F13: Operações / Enfermagem | G13: Sistemas de Informações | H13: Quality24 - Concierge: Uso da ferramenta | I13: Concluído | J13: Regiane | K13: Recorrência de baixa adesão, atraso e ausência de encerramento dos chamados.
A14: 12 | B14: 45519 | C14: Agosto | D14: 2024 | E14: HVC | F14: Enfermagem | G14: Sistemas de Informações | H14: Processo Toten PS | I14: Concluído | J14: Bianca
A15: 13 | B15: 45519 | C15: Agosto | D15: 2024 | E15: HVC | F15: Operações | G15: Fluxo do Paciente | H15: Mãe e filho descream da maternidade sem a enfermagem e sem assinar alta. recepção ligpou no posto de enfermagem, a qual pediu para paciente retornar. | I15: Concluído | J15: Rose, Milena e Milena | K15: Potencial de dano grave, exposição legal e recorrência em unidades distintas.
A16: 14 | B16: 45519 | C16: Agosto | D16: 2024 | E16: HVC | F16: Operações | G16: Infra e Hotelaria | H16: Higiene-piso liso no 1D | I16: Concluído | J16: Não informado | K16: Recorrência, pendências abertas e impacto na segurança e experiência.
A17: 15 | B17: 45519 | C17: Agosto | D17: 2024 | E17: HVC | F17: Operações | G17: Infra e Hotelaria | H17: Quebra pistola CME | I17: Concluído | J17: Januário | K17: Risco de infecção e interrupção cirúrgica com recorrência e pendências abertas.
A18: 16 | B18: 45520 | C18: Agosto | D18: 2024 | E18: HVC | F18: Assistencial | G18: Assistencial | H18: Alergia - aplicação de protocolo | I18: Concluído | J18: Deborah/ Patrícia Borges | K18: Potencial de dano grave e necessidade de barreira antes da exposição.
A19: 17 | B19: 45520 | C19: Agosto | D19: 2024 | E19: HVC | F19: Assistencial | G19: Assistencial Médico | H19: Atraso na solicitação de PICC | I19: Concluído | J19: Deborah/ Dra. Larissa | K19: Recorrência de flebite, perdas de acesso e extravasamentos.
A20: 18 | B20: 45520 | C20: Agosto | D20: 2024 | E20: HVC | F20: NSP | G20: Assistencial | H20: Reabordagem cirúrgica - gatilho (paciente 103/ dreno) | I20: Concluído | J20: Leticia/Catarina | K20: Risco cirúrgico, cancelamentos e falhas de lateralidade/material.
A21: 19 | B21: 45520 | C21: Agosto | D21: 2024 | E21: HVC | F21: Secretaria | G21: Fluxo do Paciente | H21: Processo Secretaria - novo fluxo alta ( paciente neuro internado sem acompanhante) | I21: Concluído | J21: Juliana/Lilian/ Ana Carol | K21: Recorrência e impacto em espera, ocupação e continuidade do cuidado.
A22: 20 | B22: 45520 | C22: Agosto | D22: 2024 | E22: HVC | F22: NSP | G22: Assistencial | H22: Lesão por pressão paciente centro cirúrgico | I22: Concluído | J22: Não informado | K22: Alta recorrência e potencial de prolongamento da internação.
A23: 21 | B23: 45523 | C23: Agosto | D23: 2024 | E23: HVC | F23: Operações / Enfermagem | G23: Infra e Hotelaria | H23: Controle de Acesso - maternidade | I23: Concluído | J23: Não informado | K23: Baixa frequência, porém alto potencial de dano, exposição e violação de área restrita.
A24: 22 | B24: 45523 | C24: Agosto | D24: 2024 | E24: HVC | F24: Operações | G24: Infra e Hotelaria | H24: Ar Condicionado parado - Hemodinâmica | I24: Concluído | J24: Januário | K24: Recorrência e impacto direto em áreas críticas e equipamentos.
A25: 23 | B25: 45523 | C25: Agosto | D25: 2024 | E25: HVC | F25: Operações | G25: Sistemas de Informações | H25: Nutrição atraso - Quality | I25: Concluído | J25: Regiane | K25: Recorrência de baixa adesão, atraso e ausência de encerramento dos chamados.
A26: 24 | B26: 45524 | C26: Agosto | D26: 2024 | E26: HVC | F26: PSI | G26: Assistencial | H26: Transição de criança PSI sem oxigênio | I26: Concluído | J26: Bianca
A27: 25 | B27: 45524 | C27: Agosto | D27: 2024 | E27: HVC | F27: Operações | G27: Infra e Hotelaria | H27: Higiene - estão ficando apenas 2 colaboradores - banheiro sem papel | I27: Concluído | J27: Simone | K27: Risco de queda da capacidade operacional em áreas críticas.
A28: 26 | B28: 45524 | C28: Agosto | D28: 2024 | E28: HVC | F28: Operações | G28: Infra e Hotelaria | H28: Higiene - sem colaborador na Hemodinâmica | I28: Concluído | J28: Simone | K28: Risco de queda da capacidade operacional em áreas críticas.
A29: 27 | B29: 45524 | C29: Agosto | D29: 2024 | E29: HVC | F29: Operações | G29: Infra e Hotelaria | H29: Ar condicionado no conforto médico do CC não funciona | I29: Concluído | J29: Simone | K29: Recorrência e impacto direto em áreas críticas e equipamentos.
A30: 28 | B30: 45524 | C30: Agosto | D30: 2024 | E30: HVC | F30: Operações | G30: Sistemas de Informações | H30: UTI Neo - ponto de atenção reconhecimento facil e necessidade de uma pessoa para suporte em relação ao sistema | I30: Concluído | J30: Simone e Arnaldo
A31: 29 | B31: 45524 | C31: Agosto | D31: 2024 | E31: HVC | F31: UTI Pediátrica | G31: Assistencial | H31: Troca bico mamadeira | I31: Concluído | J31: Juliana | K31: Recorrência de atrasos e risco de dieta inadequada ao paciente.
A32: 30 | B32: 45524 | C32: Agosto | D32: 2024 | E32: HVC | F32: Operações | G32: Infra e Hotelaria | H32: Reposição de água nas alas | I32: Concluído | J32: Simone
A33: 31 | B33: 45525 | C33: Agosto | D33: 2024 | E33: HVC | F33: Hemodinâmica | G33: Fluxo do Paciente | H33: Atraso na angioplastia porque médico não solicitou materiais | I33: Concluído | J33: Não informado | K33: Atrasos repetidos com cancelamentos, jejum prolongado e impacto na alta.
A34: 32 | B34: 45525 | C34: Agosto | D34: 2024 | E34: HVC | F34: Operações | G34: Infra e Hotelaria | H34: Falha de profissional de higiene na Hemodinâmica e CME | I34: Concluído | J34: Simone | K34: Risco de infecção e interrupção cirúrgica com recorrência e pendências abertas.
A35: 33 | B35: 45525 | C35: Agosto | D35: 2024 | E35: HVC | F35: Enfermagem | G35: Assistencial | H35: Clexane no 2D em horário errado | I35: Concluído | J35: Lilian | K35: Maior volume de interações priorizadas e potencial de dano evitável.
A36: 34 | B36: 45525 | C36: Agosto | D36: 2024 | E36: HVC | F36: Operações | G36: Sistemas de Informações | H36: Reconhecimento facial não funcionou a noite na UTI Neo - por questões sistêmicas, não é problema no cadastro. equipe precisa de suporte no período noturno | I36: Concluído | J36: Simone | K36: Falhas recorrentes com desvio de fluxo e aumento de filas.
A37: 35 | B37: 45526 | C37: Agosto | D37: 2024 | E37: HVC | F37: Centro Cirúrgico | G37: Assistencial | H37: Paciente fez procedimento anos atras e a chave solicitada não era compatível | I37: Concluído | J37: Não informado
A38: 36 | B38: 45526 | C38: Agosto | D38: 2024 | E38: HVC | F38: CME | G38: Infra e Hotelaria | H38: Autoclave quebrada | I38: Concluído | J38: Simone | K38: Risco de infecção e interrupção cirúrgica com recorrência e pendências abertas.
A39: 37 | B39: 45526 | C39: Agosto | D39: 2024 | E39: HVC | F39: Farmácia | G39: Assistencial | H39: Troca de medicação 6 andar (problema com prescrição) | I39: Concluído | J39: Não informado | K39: Maior volume de interações priorizadas e potencial de dano evitável.
A40: 38 | B40: 45526 | C40: Agosto | D40: 2024 | E40: HVC | F40: SCIH/CCIH | G40: Assistencial | H40: Paciente em quarto compartilhado (com necessidade de isolamento) Neta quem alertou equipe de enfermagem. | I40: Concluído | J40: Não informado | K40: Recorrência em precauções, isolamento e adesão às práticas de prevenção.
A41: 39 | B41: 45526 | C41: Agosto | D41: 2024 | E41: HVC | F41: Enfermagem Alas | G41: Infra e Hotelaria | H41: Quarto 334 com cano quebrado na madrugada | I41: Concluído | J41: Simone | K41: Alta recorrência e risco de queda, incêndio, dano patrimonial ou interrupção.
...

Sheet Pacientes Watcher
A1: Prontuário | B1: N° Atendimento | C1: Ano | D1: Paciente | E1: Nascimento | F1: Data de entrada | G1: Data Alta/óbito | H1: Setor inicial | I1: Setor final | J1: Última evolução | K1: Responsável | L1: Motivo | M1: Desfecho final | N1: Histórico de setores | O1: Observações de qualidade
A2: 509988 | B2: 6269543 | C2: 2024 | D2: RMZC | E2: 0 | F2: 45495 | G2: 45499 | H2: 3B | I2: 3B | J2: Estável | K2: Oncologia | L2: Remoção/Transporte | M2: Alta | N2: 3B | O2: Data de nascimento válida não disponível
A3: 347729 | B3: 6345785 | C3: 2024 | D3: PMMR | E3: 0 | F3: 45495 | G3: 45498 | H3: UTIA | I3: 1D | J3: Crítico | K3: Oncologia | L3: Reabordagem | M3: Óbito | N3: UTIA → 102 → 1D | O3: Data de nascimento válida não disponível
A4: 830835 | B4: 6355731 | C4: 2024 | D4: LQP | E4: 0 | F4: 45495 | G4: 45518 | H4: 1D | I4: 1D | J4: Estável | K4: Oncologia | L4: Remoção/Transporte | M4: Alta | N4: 1D | O4: Data de nascimento válida não disponível
A5: 139781 | B5: 6361323 | C5: 2024 | D5: JAB | E5: 0 | F5: 45496 | G5: 45499 | H5: 330B | I5: 330B | J5: Crítico | K5: Oncologia | L5: Deteriorização Clinica | M5: Óbito | N5: 330B | O5: Data de nascimento válida não disponível
A6: 14784 | B6: 6372412 | C6: 2024 | D6: IMFS | E6: 0 | F6: 45495 | G6: 45496 | H6: 109 | I6: 109 | J6: Crítico | K6: Oncologia | L6: Pós queixa crítica | M6: Alta | N6: 109 | O6: Data de nascimento válida não disponível
A7: 844241 | B7: 6373599 | C7: 2024 | D7: JTB | E7: 0 | F7: 45495 | G7: 45496 | H7: 713 | I7: 713 | J7: Estável | K7: Maternidade | L7: Pós queixa crítica | M7: Alta | N7: 713 | O7: Data de nascimento válida não disponível
A8: 587210 | B8: 6376082 | C8: 2024 | D8: JVML | E8: 0 | F8: 45495 | G8: 45496 | H8: 715 | I8: 715 | J8: Estável | K8: Maternidade | L8: Pós queixa crítica | M8: Alta | N8: 715 | O8: Data de nascimento válida não disponível
A9: 75196 | B9: 6376601 | C9: 2024 | D9: AB | E9: 0 | F9: 45495 | G9: 45496 | H9: 2C | I9: 2C | J9: Crítico | K9: Clínica Médica | L9: Deteriorização | M9: Óbito | N9: 2C | O9: Data de nascimento válida não disponível
A10: 6376730 | B10: 6376730 | C10: 2024 | D10: ALVL | E10: 0 | F10: 45495 | G10: 45511 | H10: 3D | I10: 3D | J10: Crítico | K10: Clínica Médica | L10: Deteriorização | M10: Alta | N10: 3D | O10: Data de nascimento válida não disponível
A11: #VALUE! | B11: 0 | C11: 2024 | D11: IMFS | E11: 0 | F11: 45495 | G11: 45498 | H11: 109 | I11: 109 | J11: Crítico | K11: Oncologia | L11: Pós queixa crítica | M11: Óbito | N11: 109 | O11: Data de nascimento válida não disponível | Prontuário não informado
A12: 6369902 | B12: 6369902 | C12: 2024 | D12: ATVN | E12: 0 | F12: 45496 | G12: 45509 | H12: 809 | I12: 809 | J12: Crítico | K12: Clínica Médica | L12: Pós queixa crítica | M12: Alta | N12: 809 | O12: Data de nascimento válida não disponível
A13: 385376 | B13: 6376582 | C13: 2024 | D13: V.M.Q | E13: 0 | F13: 45495 | G13: 45498 | H13: 426 | I13: 426 | J13: Estável | K13: Pediatria | L13: Pós evento adverso | S/Reação | M13: Alta | N13: 426 | O13: Data de nascimento válida não disponível
A14: 376178 | B14: 888712 | C14: 2024 | D14: KPPS | E14: 0 | F14: 45496 | G14: 45498 | H14: 425 | I14: 425 | J14: Estável | K14: Pediatria | L14: Pós queixa crítica | S/demandas | M14: Alta | N14: 425 | O14: Data de nascimento válida não disponível
A15: 53644 | B15: 890313 | C15: 2024 | D15: RBA | E15: 0 | F15: 45496 | G15: 45498 | H15: 707 | I15: 707 | J15: Estável | K15: Maternidade | L15: Pós queixa crítica | Resolvido | M15: Alta | N15: 707 | O15: Data de nascimento válida não disponível
A16: 475613 | B16: 6370180 | C16: 2024 | D16: SBF | E16: 27948 | F16: 45492 | G16: 45499 | H16: 216A | I16: 216A | J16: Estável | K16: Ortopedia/trauma | L16: Aguarda cirurgia | M16: Alta | N16: 216A
A17: 105488 | B17: 6370757 | C17: 2024 | D17: CV | E17: 17818 | F17: 45492 | G17: 45499 | H17: 331B | I17: 331B | J17: Estável | K17: Neurocir | L17: Risco de conflito | M17: Alta | N17: 331B
A18: 666136 | B18: 6378502 | C18: 2024 | D18: DVVL | E18: 29762 | F18: 45496 | G18: 45499 | H18: 334A | I18: 109 | J18: Estável | K18: Hematologia | L18: Quimioterapia | M18: Alta | N18: 334A → 109 | O18: Mesmas iniciais e nascimento associados a prontuários distintos: 6378502, 666136
A19: 334003 | B19: 6379812 | C19: 2024 | D19: FABLR | E19: 0 | F19: 45498 | G19: 45499 | I19: 0 | K19: 2º D | L19: Pós evento adverso | M19: Alta | N19: 0 | O19: Data de nascimento válida não disponível
A20: 794588 | B20: 794588 | C20: 2024 | D20: LRC | E20: 40066 | F20: 45489 | G20: 45555 | H20: 435 | I20: 435/430/425 | J20: Estável | K20: UTI PED/Ped | L20: Risco de conflito | M20: Alta | N20: 435 → 435/430 → 435/430/426 → 435/430/425A → 435/430/425
A21: 405850 | B21: 405850 | C21: 2024 | D21: ML | E21: 0 | F21: 45502 | G21: 45509 | H21: 8D | I21: 8D | J21: Estável | K21: Hematologia | L21: Aguarda Liberação Convênio | M21: Alta | N21: 8D | O21: Data de nascimento válida não disponível
A22: 57543 | B22: 57543 | C22: 2024 | D22: AFAS | E22: 43577 | F22: 45498 | G22: 45510 | H22: 429 | I22: 429 | J22: Estável | K22: UTI PED | L22: Pós queixa crítica | M22: Alta | N22: 429
A23: 603315 | B23: 603315 | C23: 2024 | D23: MBFB | E23: 32029 | F23: 45501 | G23: 45503 | H23: 708 | I23: 708 | J23: Estável | K23: Maternidade | L23: Risco de conflito | M23: Alta | N23: 708
A24: 666136 | B24: 666136 | C24: 2024 | D24: DVVL | E24: 29762 | F24: 45502 | G24: 45523 | H24: 104 | I24: 104 | J24: Estável | K24: Hematologia | L24: Quimioterapia | M24: Alta | N24: 104 | O24: Mesmas iniciais e nascimento associados a prontuários distintos: 6378502, 666136
A25: 891054 | B25: 891054 | C25: 2024 | D25: JMS | E25: 45201 | F25: 45501 | G25: 45504 | H25: 428 | I25: 428 | J25: Estável | K25: PED | L25: Risco de conflito | M25: Alta | N25: 428
A26: 891061 | B26: 891061 | C26: 2024 | D26: MAZG | E26: 0 | F26: 45502 | G26: 45509 | H26: 1D | I26: 1D | J26: Estável | K26: Clínica Médica | L26: Paracentese | M26: Alta | N26: 1D | O26: Data de nascimento válida não disponível
A27: 393544 | B27: 393544 | C27: 2024 | D27: MB | E27: 33190 | F27: 45504 | G27: 45505 | H27: 711 | I27: 711 | J27: Estável | K27: Maternidade | L27: Pós queixa crítica | M27: Alta | N27: 711
A28: 514378 | B28: 514378 | C28: 2024 | D28: ACV | E28: 35228 | F28: 45505 | G28: 45510 | H28: 903 | I28: 903 | J28: Estável | K28: OBS/Maternidade | L28: Risco de conflito | M28: Alta | N28: 903 → 714
A29: 557614 | B29: 557614 | C29: 2024 | D29: MASBB | E29: 31825 | F29: 45505 | G29: 45509 | H29: 713 | I29: 713 | J29: Estável | K29: Maternidade | L29: Risco de conflito | M29: Alta | N29: 713
A30: 108414 | B30: 108414 | C30: 2024 | D30: EFAL | E30: 15793 | F30: 45503 | G30: 45518 | H30: 416 | I30: 416 | J30: Estável | K30: Neurologia | L30: Reabordagem | M30: Alta | N30: 416 → 308 | O30: Mesmas iniciais e nascimento associados a prontuários distintos: 108414, 6423875
A31: 42080 | B31: 42080 | C31: 2024 | D31: JRS | E31: 19863 | F31: 45504 | G31: 45518 | H31: 802 | I31: 802 | J31: Estável | K31: Clínica Médica | L31: Reabordagem | M31: Alta | N31: 802 | O31: Mesmas iniciais e nascimento associados a prontuários distintos: 42080, 6541529 | Prontuário associado a identificações de paciente distintas
A32: 780060 | B32: 780060 | C32: 2024 | D32: BBS | E32: 44780 | F32: 45500 | G32: 45510 | H32: 428A | I32: 428A | J32: Estável | K32: Pediatria | L32: Pós queixa crítica | M32: Alta | N32: 428A
A33: 363106 | B33: 6376908 | C33: 2024 | D33: GLV | E33: 30528 | F33: 45496 | G33: 45516 | H33: 806 | I33: 806 | J33: Crítico | K33: Clínica Médica | L33: Pós queixa crítica | M33: Alta | N33: 806
A34: 394310 | B34: 394310 | C34: 2024 | D34: PAP | E34: 24473 | F34: 45506 | G34: 45518 | H34: 224 | I34: 224 | J34: Estável | K34: Cirurgia | L34: Risco de conflito | M34: Alta | N34: 224
A35: 512097 | B35: 512097 | C35: 2024 | D35: RCCN | E35: 24952 | F35: 45507 | G35: 45524 | H35: 801 | I35: 801 | J35: Estável | K35: Infecto/Ortop | L35: Pós queixa crítica | M35: Alta | N35: 801
A36: 799617 | B36: 799617 | C36: 2024 | D36: TSA | E36: 33252 | F36: 45504 | G36: 45539 | H36: 108 | I36: 302 | J36: Paliativo | K36: Oncologia | L36: Risco de conflito | M36: Óbito | N36: 108 → 310 → 302
A37: 12466 | B37: 12466 | C37: 2024 | D37: LGG | E37: 34056 | F37: 45512 | G37: 45539 | H37: 111 | I37: 111 | J37: Estável | K37: Hematologia | L37: TMO | M37: Alta | N37: 111
A38: 322003 | B38: 322003 | C38: 2024 | D38: DAMG | E38: 24696 | F38: 45512 | G38: 45530 | H38: 106 | I38: 106 | J38: Estável | K38: Hematologia | L38: TMO | M38: Alta | N38: 106
A39: 889643 | B39: 889643 | C39: 2024 | D39: DFM | E39: 45493 | F39: 45493 | G39: 45524 | H39: 503 | I39: 503 | J39: Estável | K39: UTI NEO | L39: Risco de conflito | M39: Alta | N39: 503 → 503/707
A40: 639002 | B40: 639002 | C40: 2024 | D40: VRBM | E40: 30882 | F40: 45512 | G40: 45519 | H40: 709 | I40: 709 | J40: Estável | K40: Maternidade | L40: Risco de conflito | M40: Alta | N40: 709 → 709/343
...

Sheet Foloow Up Huddle
A1: Data Ocorrência | B1: Mês | C1: Ano | D1: Unidade | E1: Área | F1: Categoria | G1: Descrição do Problema | H1: Status | I1: Responsável
A2: 45518 | B2: Agosto | C2: 2024 | D2: HVC | E2: Operações | F2: Assistencial | G2: Avental - Qualidade | H2: Concluído | I2: Simone
A3: 45518 | B3: Agosto | C3: 2024 | D3: HVC | E3: Laboratório | F3: Assistencial | G3: Hemoculturas - Atenção Global | H3: Em andamento | I3: Não informado
A4: 45518 | B4: Agosto | C4: 2024 | D4: HVC | E4: Operações / Enfermagem | F4: Sistemas de Informações | G4: Quality24 - Concierge: Adesão SLA | H4: Em andamento | I4: Simone / Lilian
A5: 45518 | B5: Agosto | C5: 2024 | D5: HVC | E5: Operações | F5: Assistencial | G5: Nutrição - atraso dieta | H5: Concluído | I5: Simone
A6: 45518 | B6: Agosto | C6: 2024 | D6: HVC | E6: Operações | F6: Infra e Hotelaria | G6: Higiene CME | H6: Concluído | I6: Simone
A7: 45518 | B7: Agosto | C7: 2024 | D7: HVC | E7: Operações | F7: Infra e Hotelaria | G7: Higiene Noturno | H7: Em andamento | I7: Simone
A8: 45518 | B8: Agosto | C8: 2024 | D8: HVC | E8: NSP | F8: Assistencial | G8: Falha na Identificação do Paciente PA | H8: Concluído | I8: Não informado
A9: 45518 | B9: Agosto | C9: 2024 | D9: HVC | E9: NSP | F9: Assistencial | G9: Número de Punções alto/ FLEBITE | H9: Em andamento | I9: Déborah
A10: 45518 | B10: Agosto | C10: 2024 | D10: HVC | E10: Enfermagem | F10: Assistencial | G10: Prótese com lateralidade errada | H10: Concluído | I10: Não informado
A11: 45518 | B11: Agosto | C11: 2024 | D11: HVC | E11: Operações | F11: Infra e Hotelaria | G11: Elevador parou com paciente entubado | H11: Concluído | I11: Januário
A12: 45518 | B12: Agosto | C12: 2024 | D12: HVC | E12: Operações / Enfermagem | F12: Sistemas de Informações | G12: Quality24 - Concierge: Uso da ferramenta | H12: Em andamento | I12: Regiane
A13: 45519 | B13: Agosto | C13: 2024 | D13: HVC | E13: Enfermagem | F13: Sistemas de Informações | G13: Processo Toten PS | H13: Concluído | I13: Bianca
... A2269: 46021 | B2269: Dezembro | C2269: 2025 | D2269: CSC | E2269: Manutenção | F2269: Infra e Hotelaria | G2269: 1 notificação ar condicionado | H2269: Concluído | I2269: Não informado
